<?xml version="1.0"?>
<robot name="/home/hugo/Documentos/RO/Practica1-RO/super_lane_pkg/resource/CitroenCZero.urdf" xmlns:xacro="http://ros.org/wiki/xacro">
  <link name="base_link">
    <visual>
      <origin xyz="1.305 0 0.15" rpy="1.570796 0 1.570796"/>
      <geometry>
        <box size="1.5 0.5 3.35"/>
      </geometry>
    </visual>
    <collision>
      <origin xyz="1.305 0 0.15" rpy="1.570796 0 1.570796"/>
      <geometry>
        <box size="1.5 0.5 3.35"/>
      </geometry>
    </collision>
    <visual>
      <origin xyz="0.575 0 0.8" rpy="1.570796 0 1.570796"/>
      <geometry>
        <box size="1.4 0.9 1.85"/>
      </geometry>
    </visual>
    <collision>
      <origin xyz="0.575 0 0.8" rpy="1.570796 0 1.570796"/>
      <geometry>
        <box size="1.4 0.9 1.85"/>
      </geometry>
    </collision>
    <visual>
      <origin xyz="1.675 0 0.4" rpy="1.570796 0 1.570796"/>
      <geometry>
        <box size="1.4 0.8 0.8"/>
      </geometry>
    </visual>
    <collision>
      <origin xyz="1.675 0 0.4" rpy="1.570796 0 1.570796"/>
      <geometry>
        <box size="1.4 0.8 0.8"/>
      </geometry>
    </collision>
    <visual>
      <origin xyz="2.115 0 0.61" rpy="2.090796 0 1.570796"/>
      <geometry>
        <box size="1.4 0.5 1.7"/>
      </geometry>
    </visual>
    <collision>
      <origin xyz="2.115 0 0.61" rpy="2.090796 0 1.570796"/>
      <geometry>
        <box size="1.4 0.5 1.7"/>
      </geometry>
    </collision>
  </link>
  <link name="backwards_lights">
  </link>
  <joint name="base_link_backwards_lights_joint" type="fixed">
    <parent link="base_link"/>
    <child link="backwards_lights"/>
    <origin xyz="0 0 0" rpy="1.570796 0 1.570796"/>
  </joint>
  <link name="rear_lights">
  </link>
  <joint name="base_link_rear_lights_joint" type="fixed">
    <parent link="base_link"/>
    <child link="rear_lights"/>
    <origin xyz="0 0 0" rpy="1.570796 0 1.570796"/>
  </joint>
  <link name="brake_lights">
  </link>
  <joint name="base_link_brake_lights_joint" type="fixed">
    <parent link="base_link"/>
    <child link="brake_lights"/>
    <origin xyz="0 0 0" rpy="1.570796 0 1.570796"/>
  </joint>
  <link name="antifog_lights">
  </link>
  <joint name="base_link_antifog_lights_joint" type="fixed">
    <parent link="base_link"/>
    <child link="antifog_lights"/>
    <origin xyz="0 0 0" rpy="1.570796 0 1.570796"/>
  </joint>
  <link name="left_indicators">
  </link>
  <joint name="base_link_left_indicators_joint" type="fixed">
    <parent link="base_link"/>
    <child link="left_indicators"/>
    <origin xyz="0 0 0" rpy="1.570796 0 1.570796"/>
  </joint>
  <link name="right_indicators">
  </link>
  <joint name="base_link_right_indicators_joint" type="fixed">
    <parent link="base_link"/>
    <child link="right_indicators"/>
    <origin xyz="0 0 0" rpy="1.570796 0 1.570796"/>
  </joint>
  <link name="front_lights">
  </link>
  <joint name="base_link_front_lights_joint" type="fixed">
    <parent link="base_link"/>
    <child link="front_lights"/>
    <origin xyz="0 0 0" rpy="1.570796 0 1.570796"/>
  </joint>
  <link name="road_camera">
  </link>
  <joint name="base_link_road_camera_joint" type="fixed">
    <parent link="base_link"/>
    <child link="road_camera"/>
    <origin xyz="2.994673 0.730216 0.38694" rpy="-1.553466 0.18405 -1.383547"/>
  </joint>
  <link name="car_camera">
  </link>
  <joint name="base_link_car_camera_joint" type="fixed">
    <parent link="base_link"/>
    <child link="car_camera"/>
    <origin xyz="2.405 0 0.92" rpy="-1.570796 0 -1.963496"/>
  </joint>
  <link name="engine_speaker">
  </link>
  <joint name="base_link_engine_speaker_joint" type="fixed">
    <parent link="base_link"/>
    <child link="engine_speaker"/>
    <origin xyz="2.55 0 0" rpy="0 0 0"/>
  </joint>
  <joint name="right_rear_wheel" type="continuous">
    <parent link="base_link"/>
    <child link="rear right wheel"/>
    <axis xyz="0 1 0"/>
    <limit effort="1e+08" velocity="174.368"/>
    <origin xyz="0 -0.635 0" rpy="0 0 0"/>
  </joint>
  <link name="rear right wheel">
    <visual>
      <origin xyz="0 0 0" rpy="1.570796 0 0"/>
      <geometry>
        <cylinder radius="0.28675" length="0.175"/>
      </geometry>
    </visual>
    <collision>
      <origin xyz="0 0 0" rpy="1.570796 0 0"/>
      <geometry>
        <cylinder radius="0.28675" length="0.175"/>
      </geometry>
    </collision>
  </link>
  <joint name="slot_rear right wheel_joint" type="fixed">
    <parent link="slot"/>
    <child link="rear right wheel"/>
    <origin xyz="0 0 0" rpy="0 0 0"/>
  </joint>
  <joint name="left_rear_wheel" type="continuous">
    <parent link="base_link"/>
    <child link="rear left wheel"/>
    <axis xyz="0 -1 0"/>
    <limit effort="1e+08" velocity="174.368"/>
    <origin xyz="0 0.635 0" rpy="0 0 3.14159"/>
  </joint>
  <link name="rear left wheel">
    <visual>
      <origin xyz="0 0 0" rpy="1.570796 0 0"/>
      <geometry>
        <cylinder radius="0.28675" length="0.175"/>
      </geometry>
    </visual>
    <collision>
      <origin xyz="0 0 0" rpy="1.570796 0 0"/>
      <geometry>
        <cylinder radius="0.28675" length="0.175"/>
      </geometry>
    </collision>
  </link>
  <joint name="slot_0_rear left wheel_joint" type="fixed">
    <parent link="slot_0"/>
    <child link="rear left wheel"/>
    <origin xyz="0 0 0" rpy="0 0 0"/>
  </joint>
</robot>
